2022-09-15 11:18:06,444 - source - SourceWorkers - ERROR - {"channel": "resource_request", "event": "Exception running source factoryglobal_manifests ", "exception": "Traceback (most recent call last):\n  File \"/home/de1/decisionengine/src/decisionengine/framework/engine/SourceWorkers.py\", line 161, in run\n    Module.verify_products(self.module_instance, data)\n  File \"/home/de1/decisionengine/src/decisionengine/framework/modules/Module.py\", line 113, in verify_products\n    raise RuntimeError(err_msg)\nRuntimeError: \nThe following products have the wrong types:\n - 'factoryglobal_manifests' (expected 'DataFrame', got 'NoneType')\n", "level": "error", "logger": "source", "module": "factoryglobal_manifests", "timestamp": "2022-09-15 11:18:06"}
